{
 "cells": [
  {
   "cell_type": "markdown",
   "metadata": {},
   "source": [
    "<h>-------------------------------Exception Handling--------------------------</h>"
   ]
  },
  {
   "cell_type": "markdown",
   "metadata": {},
   "source": [
    "<h>--> Types of Error in Python Programming and their solutions using exception handling\n",
    "<p> 1. Syntax error</p>\n",
    "<h> 2. Name error</p>\n",
    "<h> 3. Index error<p>\n",
    "<p> 4. Zero Division error</p>\n",
    "<p> 5. File not Found error</p>\n",
    "<p> 6. File existing error</p>\n"
   ]
  },
  {
   "cell_type": "markdown",
   "metadata": {},
   "source": [
    "\n",
    "\n",
    "\n",
    "<h>1. Syntax error:- </h5>\n",
    "<p>When the interpreter comes across an invalid syntax while writing Python code, a SyntaxError is said to occur. Usually, the interpreter parses the Python code to convert it into bytecode and on encountering any invalid syntax in the parsing stage, it throws an error called the SyntaxError.\n",
    "\n",
    " \n"
   ]
  },
  {
   "cell_type": "code",
   "execution_count": 2,
   "metadata": {},
   "outputs": [
    {
     "ename": "SyntaxError",
     "evalue": "invalid syntax. Perhaps you forgot a comma? (1617114799.py, line 1)",
     "output_type": "error",
     "traceback": [
      "\u001b[1;36m  Cell \u001b[1;32mIn[2], line 1\u001b[1;36m\u001b[0m\n\u001b[1;33m    print(this is my syntax error)\u001b[0m\n\u001b[1;37m          ^\u001b[0m\n\u001b[1;31mSyntaxError\u001b[0m\u001b[1;31m:\u001b[0m invalid syntax. Perhaps you forgot a comma?\n"
     ]
    }
   ],
   "source": [
    "print(this is my syntax error)\n",
    "name=(input(\"enter your name \"))\n",
    "print(name)"
   ]
  },
  {
   "cell_type": "code",
   "execution_count": 2,
   "metadata": {},
   "outputs": [
    {
     "name": "stdout",
     "output_type": "stream",
     "text": [
      "Hlo, welcome to the secction of exception handling in Python\n",
      "In this we will look towards the error in python and how we can handle them \n",
      "there was syntax error in your try block:\n",
      "so please correct that error\n",
      "it doesnt matter there is error in your programme is not but this block will always run\n",
      "you are adding the b and c\n",
      "17\n"
     ]
    }
   ],
   "source": [
    "print(\"Hlo, welcome to the secction of exception handling in Python\")\n",
    "print(\"In this we will look towards the error in python and how we can handle them \")\n",
    "# if we will code prinnt(\"wecome \") than it will show error but if i will put it in try block than it will not show \n",
    "# error it will first try to run than that Block and if there will be error that cannot resolve than\n",
    "# it will pass it to next block name Except\n",
    "# lets see\n",
    "try:\n",
    "    print(this is my syntax error)\n",
    "    name=(input(\"enter your name \"))\n",
    "    print(name)\n",
    "except:\n",
    "    print(\"there was syntax error in your try block:\")\n",
    "    print(\"so please correct that error\")\n",
    "else:\n",
    "    print(\"congratulations, there was no syntax error in your programme\")\n",
    "    \n",
    "\n",
    "finally:\n",
    "    print(\"it doesnt matter there is error in your programme is not but this block will always run\")\n",
    "    b=8\n",
    "    c=9\n",
    "    print(\"you are adding the b and c\")\n",
    "    print(b+c)"
   ]
  },
  {
   "cell_type": "markdown",
   "metadata": {},
   "source": [
    "\n",
    "<h5>2. Name error </h5>\n",
    "<p>we know that python is a case sensitive language show if we are writing a and A than these are two different varibles and in the case we want to print a and we are writing print(A) in our code than it will be error and this error is known as Name error\n"
   ]
  },
  {
   "cell_type": "code",
   "execution_count": 4,
   "metadata": {},
   "outputs": [
    {
     "name": "stdout",
     "output_type": "stream",
     "text": [
      "Name error in python\n"
     ]
    },
    {
     "ename": "NameError",
     "evalue": "name 'B' is not defined",
     "output_type": "error",
     "traceback": [
      "\u001b[1;31m---------------------------------------------------------------------------\u001b[0m",
      "\u001b[1;31mNameError\u001b[0m                                 Traceback (most recent call last)",
      "Cell \u001b[1;32mIn[4], line 4\u001b[0m\n\u001b[0;32m      2\u001b[0m a\u001b[38;5;241m=\u001b[39m\u001b[38;5;241m9\u001b[39m\n\u001b[0;32m      3\u001b[0m b\u001b[38;5;241m=\u001b[39m\u001b[38;5;241m7\u001b[39m\n\u001b[1;32m----> 4\u001b[0m \u001b[38;5;28mprint\u001b[39m(a\u001b[38;5;241m+\u001b[39m\u001b[43mB\u001b[49m)\n\u001b[0;32m      5\u001b[0m \u001b[38;5;66;03m# this will show error and it is a name error\u001b[39;00m\n",
      "\u001b[1;31mNameError\u001b[0m: name 'B' is not defined"
     ]
    }
   ],
   "source": [
    "print(\"Name error in python\")\n",
    "a=9\n",
    "b=7\n",
    "print(a+B)\n",
    "# this will show error and it is a name error\n",
    "\n",
    "\n"
   ]
  },
  {
   "cell_type": "markdown",
   "metadata": {},
   "source": [
    "<p>Solution of Name error using Exception Handling <p>"
   ]
  },
  {
   "cell_type": "code",
   "execution_count": 5,
   "metadata": {},
   "outputs": [
    {
     "name": "stdout",
     "output_type": "stream",
     "text": [
      "there was name error in your above programme\n",
      "thats why except blocks execute here\n"
     ]
    }
   ],
   "source": [
    "# if we want to run the above programme without any error than we will again use exception \n",
    "# handling \n",
    "\n",
    "try:\n",
    "    a=2\n",
    "    b=3\n",
    "    print(A+B) # doubt to ask \n",
    "\n",
    "    c=a*b\n",
    "    print(c) # this will show syntax error \n",
    "\n",
    "except:\n",
    "    print(\"there was name error in your above programme\")\n",
    "    print(\"thats why except blocks execute here\")\n",
    "    \n",
    "\n",
    "    "
   ]
  },
  {
   "cell_type": "markdown",
   "metadata": {},
   "source": [
    "<h5>3. Index error</h5>\n",
    "<p>In Python, the IndexError is a common exception that occurs when trying to access an element in a list, tuple, or any other sequence using an index that is outside the valid range of indices for that sequence.</p>\n"
   ]
  },
  {
   "cell_type": "code",
   "execution_count": 1,
   "metadata": {},
   "outputs": [
    {
     "ename": "IndexError",
     "evalue": "list index out of range",
     "output_type": "error",
     "traceback": [
      "\u001b[1;31m---------------------------------------------------------------------------\u001b[0m",
      "\u001b[1;31mIndexError\u001b[0m                                Traceback (most recent call last)",
      "Cell \u001b[1;32mIn[1], line 3\u001b[0m\n\u001b[0;32m      1\u001b[0m \u001b[38;5;66;03m# index error \u001b[39;00m\n\u001b[0;32m      2\u001b[0m lst\u001b[38;5;241m=\u001b[39m[\u001b[38;5;241m12\u001b[39m,\u001b[38;5;241m34\u001b[39m,\u001b[38;5;241m56\u001b[39m,\u001b[38;5;241m23\u001b[39m,\u001b[38;5;241m78\u001b[39m,\u001b[38;5;241m56\u001b[39m]\n\u001b[1;32m----> 3\u001b[0m \u001b[38;5;28mprint\u001b[39m(\u001b[43mlst\u001b[49m\u001b[43m[\u001b[49m\u001b[38;5;241;43m6\u001b[39;49m\u001b[43m]\u001b[49m)\n",
      "\u001b[1;31mIndexError\u001b[0m: list index out of range"
     ]
    }
   ],
   "source": [
    "# index error \n",
    "lst=[12,34,56,23,78,56]\n",
    "print(lst[6])\n"
   ]
  },
  {
   "cell_type": "markdown",
   "metadata": {},
   "source": [
    "<p> Soution of Index Error :-<p>"
   ]
  },
  {
   "cell_type": "code",
   "execution_count": 2,
   "metadata": {},
   "outputs": [
    {
     "name": "stdout",
     "output_type": "stream",
     "text": [
      "there is index error in your programme \n",
      "Kindly give the correct index\n",
      "thank you\n"
     ]
    }
   ],
   "source": [
    "# so in above cell there was the index error because we try to print the index that doent exist \n",
    "# therefore it is showing idex error\n",
    "# here we will look that how we can ignore this error with the help of exception handling \n",
    "try:\n",
    "    print(lst[6])\n",
    "    print(lst[0:3])\n",
    "except:\n",
    "    print(\"there is index error in your programme \")\n",
    "    print(\"Kindly give the correct index\")\n",
    "    print(\"thank you\")\n",
    "    \n",
    "    "
   ]
  },
  {
   "cell_type": "markdown",
   "metadata": {},
   "source": [
    "<h5>4. Zero Division error </h5>\n",
    "<p>A ZeroDivisionError in Python occurs when we try to divide a number by 0. We can’t divide a number by 0 otherwise it will raise an error.<p>"
   ]
  },
  {
   "cell_type": "code",
   "execution_count": 3,
   "metadata": {},
   "outputs": [
    {
     "ename": "ZeroDivisionError",
     "evalue": "division by zero",
     "output_type": "error",
     "traceback": [
      "\u001b[1;31m---------------------------------------------------------------------------\u001b[0m",
      "\u001b[1;31mZeroDivisionError\u001b[0m                         Traceback (most recent call last)",
      "Cell \u001b[1;32mIn[3], line 4\u001b[0m\n\u001b[0;32m      2\u001b[0m num1\u001b[38;5;241m=\u001b[39m\u001b[38;5;28mint\u001b[39m(\u001b[38;5;28minput\u001b[39m(\u001b[38;5;124m\"\u001b[39m\u001b[38;5;124menter the number 1\u001b[39m\u001b[38;5;124m\"\u001b[39m))\n\u001b[0;32m      3\u001b[0m num2\u001b[38;5;241m=\u001b[39m\u001b[38;5;28mint\u001b[39m(\u001b[38;5;28minput\u001b[39m(\u001b[38;5;124m\"\u001b[39m\u001b[38;5;124menter the number 2\u001b[39m\u001b[38;5;124m\"\u001b[39m))\n\u001b[1;32m----> 4\u001b[0m \u001b[38;5;28mprint\u001b[39m(\u001b[43mnum1\u001b[49m\u001b[38;5;241;43m/\u001b[39;49m\u001b[43mnum2\u001b[49m)\n",
      "\u001b[1;31mZeroDivisionError\u001b[0m: division by zero"
     ]
    }
   ],
   "source": [
    "# zero division error \n",
    "num1=int(input(\"enter the number 1\"))\n",
    "num2=int(input(\"enter the number 2\"))\n",
    "print(num1/num2)\n",
    "\n"
   ]
  },
  {
   "cell_type": "markdown",
   "metadata": {},
   "source": [
    "<p>So, we can clearly see from the above cell there is zero division error because we cannot divide the number by zero digit </p>\n",
    "<p>to avoid this error we will use try and excpt block in our programme </p>"
   ]
  },
  {
   "cell_type": "code",
   "execution_count": 5,
   "metadata": {},
   "outputs": [
    {
     "name": "stdout",
     "output_type": "stream",
     "text": [
      "there is zero division Error in your Programme \n",
      "you cannot divide the any digit by zero\n"
     ]
    }
   ],
   "source": [
    "try :\n",
    "    num1=int(input(\"enter the number 1\"))\n",
    "    num2=int(input(\"enter the number 2\"))\n",
    "    print(num1/num2)\n",
    "except:\n",
    "    print(\"there is zero division Error in your Programme \")\n",
    "    print(\"you cannot divide the any digit by zero\")\n",
    "    \n"
   ]
  },
  {
   "cell_type": "markdown",
   "metadata": {},
   "source": [
    "<h>5 . File not found error </h>\n",
    "<p> This error will be shown if we are trying to opening a file that doent exist</p>"
   ]
  },
  {
   "cell_type": "code",
   "execution_count": 9,
   "metadata": {},
   "outputs": [
    {
     "ename": "FileNotFoundError",
     "evalue": "[Errno 2] No such file or directory: 'demo3.txt'",
     "output_type": "error",
     "traceback": [
      "\u001b[1;31m---------------------------------------------------------------------------\u001b[0m",
      "\u001b[1;31mFileNotFoundError\u001b[0m                         Traceback (most recent call last)",
      "Cell \u001b[1;32mIn[9], line 1\u001b[0m\n\u001b[1;32m----> 1\u001b[0m file\u001b[38;5;241m=\u001b[39m\u001b[38;5;28;43mopen\u001b[39;49m\u001b[43m(\u001b[49m\u001b[38;5;124;43m\"\u001b[39;49m\u001b[38;5;124;43mdemo3.txt\u001b[39;49m\u001b[38;5;124;43m\"\u001b[39;49m\u001b[43m)\u001b[49m\n\u001b[0;32m      2\u001b[0m file\u001b[38;5;241m.\u001b[39mclose()\n",
      "File \u001b[1;32m~\\AppData\\Roaming\\Python\\Python312\\site-packages\\IPython\\core\\interactiveshell.py:324\u001b[0m, in \u001b[0;36m_modified_open\u001b[1;34m(file, *args, **kwargs)\u001b[0m\n\u001b[0;32m    317\u001b[0m \u001b[38;5;28;01mif\u001b[39;00m file \u001b[38;5;129;01min\u001b[39;00m {\u001b[38;5;241m0\u001b[39m, \u001b[38;5;241m1\u001b[39m, \u001b[38;5;241m2\u001b[39m}:\n\u001b[0;32m    318\u001b[0m     \u001b[38;5;28;01mraise\u001b[39;00m \u001b[38;5;167;01mValueError\u001b[39;00m(\n\u001b[0;32m    319\u001b[0m         \u001b[38;5;124mf\u001b[39m\u001b[38;5;124m\"\u001b[39m\u001b[38;5;124mIPython won\u001b[39m\u001b[38;5;124m'\u001b[39m\u001b[38;5;124mt let you open fd=\u001b[39m\u001b[38;5;132;01m{\u001b[39;00mfile\u001b[38;5;132;01m}\u001b[39;00m\u001b[38;5;124m by default \u001b[39m\u001b[38;5;124m\"\u001b[39m\n\u001b[0;32m    320\u001b[0m         \u001b[38;5;124m\"\u001b[39m\u001b[38;5;124mas it is likely to crash IPython. If you know what you are doing, \u001b[39m\u001b[38;5;124m\"\u001b[39m\n\u001b[0;32m    321\u001b[0m         \u001b[38;5;124m\"\u001b[39m\u001b[38;5;124myou can use builtins\u001b[39m\u001b[38;5;124m'\u001b[39m\u001b[38;5;124m open.\u001b[39m\u001b[38;5;124m\"\u001b[39m\n\u001b[0;32m    322\u001b[0m     )\n\u001b[1;32m--> 324\u001b[0m \u001b[38;5;28;01mreturn\u001b[39;00m \u001b[43mio_open\u001b[49m\u001b[43m(\u001b[49m\u001b[43mfile\u001b[49m\u001b[43m,\u001b[49m\u001b[43m \u001b[49m\u001b[38;5;241;43m*\u001b[39;49m\u001b[43margs\u001b[49m\u001b[43m,\u001b[49m\u001b[43m \u001b[49m\u001b[38;5;241;43m*\u001b[39;49m\u001b[38;5;241;43m*\u001b[39;49m\u001b[43mkwargs\u001b[49m\u001b[43m)\u001b[49m\n",
      "\u001b[1;31mFileNotFoundError\u001b[0m: [Errno 2] No such file or directory: 'demo3.txt'"
     ]
    }
   ],
   "source": [
    "file=open(\"demo3.txt\")\n",
    "file.close()\n"
   ]
  },
  {
   "cell_type": "markdown",
   "metadata": {},
   "source": [
    "<p3>The above cell is clearly showing the file not found error, because the file demo3.txt that doen't exist in our directory or system </p3>\n"
   ]
  },
  {
   "cell_type": "markdown",
   "metadata": {},
   "source": [
    "<h5> 6. File Existing error</h5>\n",
    "    <pI> If the file already exist in our system and we are again trying to make that file within our directory using \"x\" mode than it will create an error and that error is known as file existing error "
   ]
  },
  {
   "cell_type": "code",
   "execution_count": 10,
   "metadata": {},
   "outputs": [
    {
     "ename": "FileExistsError",
     "evalue": "[Errno 17] File exists: 'demo2.txt'",
     "output_type": "error",
     "traceback": [
      "\u001b[1;31m---------------------------------------------------------------------------\u001b[0m",
      "\u001b[1;31mFileExistsError\u001b[0m                           Traceback (most recent call last)",
      "Cell \u001b[1;32mIn[10], line 1\u001b[0m\n\u001b[1;32m----> 1\u001b[0m data\u001b[38;5;241m=\u001b[39m\u001b[38;5;28;43mopen\u001b[39;49m\u001b[43m(\u001b[49m\u001b[38;5;124;43m\"\u001b[39;49m\u001b[38;5;124;43mdemo2.txt\u001b[39;49m\u001b[38;5;124;43m\"\u001b[39;49m\u001b[43m,\u001b[49m\u001b[38;5;124;43m'\u001b[39;49m\u001b[38;5;124;43mx\u001b[39;49m\u001b[38;5;124;43m'\u001b[39;49m\u001b[43m)\u001b[49m\n\u001b[0;32m      2\u001b[0m data\u001b[38;5;241m.\u001b[39mclose()\n",
      "File \u001b[1;32m~\\AppData\\Roaming\\Python\\Python312\\site-packages\\IPython\\core\\interactiveshell.py:324\u001b[0m, in \u001b[0;36m_modified_open\u001b[1;34m(file, *args, **kwargs)\u001b[0m\n\u001b[0;32m    317\u001b[0m \u001b[38;5;28;01mif\u001b[39;00m file \u001b[38;5;129;01min\u001b[39;00m {\u001b[38;5;241m0\u001b[39m, \u001b[38;5;241m1\u001b[39m, \u001b[38;5;241m2\u001b[39m}:\n\u001b[0;32m    318\u001b[0m     \u001b[38;5;28;01mraise\u001b[39;00m \u001b[38;5;167;01mValueError\u001b[39;00m(\n\u001b[0;32m    319\u001b[0m         \u001b[38;5;124mf\u001b[39m\u001b[38;5;124m\"\u001b[39m\u001b[38;5;124mIPython won\u001b[39m\u001b[38;5;124m'\u001b[39m\u001b[38;5;124mt let you open fd=\u001b[39m\u001b[38;5;132;01m{\u001b[39;00mfile\u001b[38;5;132;01m}\u001b[39;00m\u001b[38;5;124m by default \u001b[39m\u001b[38;5;124m\"\u001b[39m\n\u001b[0;32m    320\u001b[0m         \u001b[38;5;124m\"\u001b[39m\u001b[38;5;124mas it is likely to crash IPython. If you know what you are doing, \u001b[39m\u001b[38;5;124m\"\u001b[39m\n\u001b[0;32m    321\u001b[0m         \u001b[38;5;124m\"\u001b[39m\u001b[38;5;124myou can use builtins\u001b[39m\u001b[38;5;124m'\u001b[39m\u001b[38;5;124m open.\u001b[39m\u001b[38;5;124m\"\u001b[39m\n\u001b[0;32m    322\u001b[0m     )\n\u001b[1;32m--> 324\u001b[0m \u001b[38;5;28;01mreturn\u001b[39;00m \u001b[43mio_open\u001b[49m\u001b[43m(\u001b[49m\u001b[43mfile\u001b[49m\u001b[43m,\u001b[49m\u001b[43m \u001b[49m\u001b[38;5;241;43m*\u001b[39;49m\u001b[43margs\u001b[49m\u001b[43m,\u001b[49m\u001b[43m \u001b[49m\u001b[38;5;241;43m*\u001b[39;49m\u001b[38;5;241;43m*\u001b[39;49m\u001b[43mkwargs\u001b[49m\u001b[43m)\u001b[49m\n",
      "\u001b[1;31mFileExistsError\u001b[0m: [Errno 17] File exists: 'demo2.txt'"
     ]
    }
   ],
   "source": [
    "data=open(\"demo2.txt\",'x')\n",
    "data.close()"
   ]
  },
  {
   "cell_type": "markdown",
   "metadata": {},
   "source": [
    "<h> 7. Attribute Error</h>\n",
    "<p> if we take a variable x we are assigned a value of 10. In this process suppose we want to append another value to that variable. It’s not possible. Because the variable is an integer type it does not support the append method. So in this type of problem, we get an error called “AttributeError”.\n",
    "<p>AttributeError can also be raised for a user-defined class when the user tries to make an invalid attribute reference.\n"
   ]
  },
  {
   "cell_type": "code",
   "execution_count": 7,
   "metadata": {},
   "outputs": [
    {
     "ename": "AttributeError",
     "evalue": "'student' object has no attribute 'student_pho'",
     "output_type": "error",
     "traceback": [
      "\u001b[1;31m---------------------------------------------------------------------------\u001b[0m",
      "\u001b[1;31mAttributeError\u001b[0m                            Traceback (most recent call last)",
      "Cell \u001b[1;32mIn[7], line 10\u001b[0m\n\u001b[0;32m      7\u001b[0m         \u001b[38;5;28mprint\u001b[39m(\u001b[38;5;28mself\u001b[39m\u001b[38;5;241m.\u001b[39mstudent_id)\n\u001b[0;32m      9\u001b[0m obj\u001b[38;5;241m=\u001b[39mstudent()\n\u001b[1;32m---> 10\u001b[0m \u001b[43mobj\u001b[49m\u001b[38;5;241;43m.\u001b[39;49m\u001b[43mstudent_pho\u001b[49m\n",
      "\u001b[1;31mAttributeError\u001b[0m: 'student' object has no attribute 'student_pho'"
     ]
    }
   ],
   "source": [
    "class student:\n",
    "    studetn_address=\"jaipur\"\n",
    "    def __init__(self) :\n",
    "        self.student_name=\"Madhav Sharma\"\n",
    "        self.student_id=\"22038\"\n",
    "    def display1(self):\n",
    "        print(self.student_id)\n",
    "        \n",
    "obj=student()\n",
    "obj.student_pho\n",
    "    \n",
    "    "
   ]
  },
  {
   "cell_type": "markdown",
   "metadata": {},
   "source": [
    "<p> So we can clearly see the above cell is Showing attribute error "
   ]
  },
  {
   "cell_type": "code",
   "execution_count": 8,
   "metadata": {},
   "outputs": [
    {
     "name": "stdout",
     "output_type": "stream",
     "text": [
      "there was attribute error in your programme\n",
      "there is no data of student phone \n"
     ]
    }
   ],
   "source": [
    "class student:\n",
    "    studetn_address=\"jaipur\"\n",
    "    def __init__(self) :\n",
    "        self.student_name=\"Madhav Sharma\"\n",
    "        self.student_id=\"22038\"\n",
    "    def display1(self):\n",
    "        print(self.student_id)\n",
    "\n",
    "try:       \n",
    "    obj=student()\n",
    "    obj.student_pho\n",
    "except:\n",
    "    print(\"there was attribute error in your programme\")\n",
    "    print(\"there is no data of student phone \")"
   ]
  }
 ],
 "metadata": {
  "kernelspec": {
   "display_name": "Python 3",
   "language": "python",
   "name": "python3"
  },
  "language_info": {
   "codemirror_mode": {
    "name": "ipython",
    "version": 3
   },
   "file_extension": ".py",
   "mimetype": "text/x-python",
   "name": "python",
   "nbconvert_exporter": "python",
   "pygments_lexer": "ipython3",
   "version": "3.12.4"
  }
 },
 "nbformat": 4,
 "nbformat_minor": 2
}
